<?xml version="1.0"?>
<robot xmlns:xacro="http://www.ros.org/wiki/xacro" >
    <joint name="RTx" type="revolute">
        <origin xyz="0 0 0" rpy="0 0 0"/>
        <parent link="Right_HipMount"/>
        <child link="Right_Hip"/>
        <axis xyz="1.0 0 0"/>
        <limit lower="${-pi/2}" upper="${pi/2}" effort="100" velocity="100"/>
    </joint>
    <link name="Right_Hip">
        <visual>
            <origin xyz="0 0 0" rpy="0 0 0"/>
            <geometry>
                <mesh filename="file://$(find ros2_humanoid_virtual_twin)/meshes/Right-Hip.stl"/>
            </geometry>
            <material name="grey"/>
        </visual>
        <collision>
            <origin xyz="0 0 0" rpy="0 0 0"/>
            <geometry>
                <mesh filename="file://$(find ros2_humanoid_virtual_twin)/meshes/Right-Hip-Collision.stl"/>
            </geometry>
        </collision>
        <inertial>
            <origin xyz="-21.137e-06 0.17e-03 14.739e-03" rpy="0 0 0"/>
            <mass value="0.351"/>       
            <inertia ixx="135.823e-6" iyy="317.524e-6" izz="266.663e-6" ixy="-1.265e-6" ixz="4.25e-6"  iyz="2.029e-6" />  
        </inertial>
    </link>
    <gazebo reference="Right_Hip">
        <material>Gazebo/Grey</material>
        <mu1 value="${mu1_val}"/>
        <mu2 value="${mu2_val}"/>
        <kp value="${kp_val}" />
        <kd value="${kd_val}" />
        <maxVel value="${maxVel_val}"/>
        <selfCollide>${selfCollide_val}</selfCollide>  
    </gazebo>
</robot>
