<?xml version="1.0"?>
<robot xmlns:xacro="http://www.ros.org/wiki/xacro">
    <joint name="RTz" type="revolute">
        <origin xyz="0 -40e-03 -150.065e-03" rpy="0 0 0"/>
        <parent link="Trunk"/>
        <child link="Right_HipMount"/>
        <axis xyz="0 0 1.0"/>
        <limit lower="${-pi/2}" upper="${pi/2}" effort="${maxeffort_val}" velocity="${maxVel_val}"/>
        <xacro:if value="$(arg use_URDF_joint_dynamics_coefficients)">
            <dynamics damping="${damping_val}" friction="${friction_val}"/>
        </xacro:if>
    </joint>
    <link name="Right_HipMount">
        <visual>
            <origin xyz="0 0 0" rpy="0 0 0"/>
            <geometry>
                <mesh filename="file://$(find ros2_humanoid_virtual_twin)/meshes/Right-HipMount.stl"/>
            </geometry>
            <material name="grey"/>
        </visual>
        <collision>
            <origin xyz="0 0 0" rpy="0 0 0"/>
            <geometry>
                <mesh filename="file://$(find ros2_humanoid_virtual_twin)/meshes/Right-HipMount-Collision.stl"/>
            </geometry>
        </collision>
        <inertial>
            <origin xyz="-13.999e-3	0	24.592e-3" rpy="0 0 0"/>
            <mass value="0.036"/>
            <inertia ixx="11.125e-6" iyy="57.759e-6" izz="55.215e-6" ixy="0" ixz="4.397e-6"  iyz="0" />
        </inertial>
    </link>
    <xacro:if value="$(arg use_gazebo_joint_physics_coefficients)">
    <gazebo reference="RTz">
        <implicitSpringDamper>${Damper_val}</implicitSpringDamper>
        <springStiffness>${springstiffness_val}</springStiffness>
        <springReference>${springReference_val}</springReference>
        <stopErp>${stopErp_val}</stopErp>
        <stopCfm>${stopCfm_val}</stopCfm>
    </gazebo>
    </xacro:if>
    <gazebo reference="Right_HipMount">
        <material>Gazebo/Grey</material>
        <xacro:if value="$(arg use_gazebo_link_physics_coefficients)">
          <mu1 value="${mu1_val}"/>
          <mu2 value="${mu2_val}"/>
          <kp value="${kp_val}" />
          <kd value="${kd_val}" />
          <maxVel value="${maxVel_val}"/>
          <dampingFactor value="${dampigFactor_val}"/>
          <selfCollide>${selfCollide_val}</selfCollide>  
        </xacro:if>
    </gazebo>
</robot>