<?xml version="1.0"?>
<robot xmlns:xacro="http://www.ros.org/wiki/xacro" >
    <joint name="RTx" type="revolute">
        <origin xyz="0 0 0" rpy="0 0 0"/>
        <parent link="Right_HipMount"/>
        <child link="Right_Hip"/>
        <axis xyz="1.0 0 0"/>
        <limit lower="${-pi/2}" upper="${pi/2}" effort="${maxeffort_val}" velocity="${maxVel_val}"/>
        <xacro:if value="$(arg use_URDF_joint_dynamics_coefficients)">
            <dynamics damping="${damping_val}" friction="${friction_val}"/>
        </xacro:if>
    </joint>
    <link name="Right_Hip">
        <visual>
            <origin xyz="0 0 0" rpy="0 0 0"/>
            <geometry>
                <mesh filename="file://$(find ros2_humanoid_virtual_twin)/meshes/Right-Hip.stl"/>
            </geometry>
            <material name="grey"/>
        </visual>
        <collision>
            <origin xyz="0 0 0" rpy="0 0 0"/>
            <geometry>
                <mesh filename="file://$(find ros2_humanoid_virtual_twin)/meshes/Right-Hip-Collision.stl"/>
            </geometry>
        </collision>
        <inertial>
            <origin xyz="-21.137e-06 0.17e-03 14.739e-03" rpy="0 0 0"/>
            <mass value="0.351"/>       
            <inertia ixx="135.823e-6" iyy="317.524e-6" izz="266.663e-6" ixy="-1.265e-6" ixz="4.25e-6"  iyz="2.029e-6" />  
        </inertial>
    </link>
    <xacro:if value="$(arg use_gazebo_joint_physics_coefficients)">
    <gazebo reference="RTx">
        <implicitSpringDamper>${Damper_val}</implicitSpringDamper>
        <springStiffness>${springstiffness_val}</springStiffness>
        <springReference>${springReference_val}</springReference>
        <stopErp>${stopErp_val}</stopErp>
        <stopCfm>${stopCfm_val}</stopCfm>
    </gazebo>    
    </xacro:if>
    <gazebo reference="Right_Hip">
        <material>Gazebo/Grey</material>
        <xacro:if value="$(arg use_gazebo_link_physics_coefficients)">
          <mu1 value="${mu1_val}"/>
          <mu2 value="${mu2_val}"/>
          <kp value="${kp_val}" />
          <kd value="${kd_val}" />
          <maxVel value="${maxVel_val}"/>
          <dampingFactor value="${dampigFactor_val}"/>
          <selfCollide>${selfCollide_val}</selfCollide>  
        </xacro:if> 
    </gazebo>
</robot>
