<?xml version="1.0"?>
<robot xmlns:xacro="http://www.ros.org/wiki/xacro" >
    <joint name="LAx" type="revolute">
        <origin xyz="0 0 0" rpy="0 0 0"/>
        <parent link="Left_ArmMounting"/>
        <child link="Left_Arm"/>
        <axis xyz="1.0 0 0"/>
        <limit lower="${-pi/2}" upper="${pi/2}" effort="${maxeffort_val}" velocity="${maxVel_val}"/>
        <xacro:if value="$(arg use_URDF_joint_dynamics_coefficients)">
            <dynamics damping="${damping_val}" friction="${friction_val}"/>
        </xacro:if>
    </joint>
    <link name="Left_Arm">
        <visual>
            <origin xyz="0 0 0" rpy="0 0 0"/>
            <geometry>
                <mesh filename="file://$(find ros2_humanoid_virtual_twin)/meshes/Left-Arm.stl" scale="0.001 0.001 0.001"/>
            </geometry>
            <material name="grey"/>
        </visual>
        <collision>
            <origin xyz="0 0 0" rpy="0 0 0"/>
            <geometry>
                <mesh filename="file://$(find ros2_humanoid_virtual_twin)/meshes/Left-Arm_Collision.stl" scale="0.001 0.001 0.001"/>
            </geometry>
        </collision>
        <inertial>
            <origin xyz="0.152e-3 -0.087e-3 -49.855e-3" rpy="0 0 0"/>
            <mass value="0.165"/>
            <inertia ixx="269.772e-6" iyy="269.138e-6" izz="29.837e-6" ixy="-0.02e-6" ixz="-1.454e-6"  iyz="-0.269e-6"/>
        </inertial>
    </link>
    <xacro:if value="$(arg use_gazebo_joint_physics_coefficients)">
    <gazebo reference="LAx">
        <implicitSpringDamper>${Damper_val}</implicitSpringDamper>
        <springStiffness>${springstiffness_val}</springStiffness>
        <springReference>${springReference_val}</springReference>
        <stopErp>${stopErp_val}</stopErp>
        <stopCfm>${stopCfm_val}</stopCfm>
    </gazebo>    
    </xacro:if>
    <gazebo reference="Left_Arm">
        <material>Gazebo/Grey</material>
        <xacro:if value="$(arg use_gazebo_link_physics_coefficients)">
          <mu1 value="${mu1_val}"/>
          <mu2 value="${mu2_val}"/>
          <kp value="${kp_val}" />
          <kd value="${kd_val}" />
          <maxVel value="${maxVel_val}"/>
          <dampingFactor value="${dampigFactor_val}"/>
          <selfCollide>${selfCollide_val}</selfCollide>  
        </xacro:if>
    </gazebo>
</robot>
  