<?xml version="1.0"?>
<robot xmlns:xacro="http://www.ros.org/wiki/xacro" >
    <joint name="LFAy" type="revolute">
        <origin xyz="0 0 -112.3e-3" rpy="0 0 0"/>
        <parent link="Left_Arm"/>
        <child link="Left_Forearm"/>
        <axis xyz="0 1.0 0"/>
        <limit lower="${-pi/2}" upper="${pi/2}" effort="1" velocity="1"/>
    </joint>
    <link name="Left_Forearm">
        <visual>
            <origin xyz="0 0 0" rpy="0 0 0"/>
            <geometry>
                <mesh filename="file://$(find ros2_humanoid_virtual_twin)/meshes/Left_ForeArm.stl" scale="0.001 0.001 0.001"/>
            </geometry>
            <material name="grey"/>
        </visual>
        <!-- <collision>
            <origin xyz="0 0 0" rpy="0 0 0"/>
            <geometry>
                <mesh filename="file://$(find ros2_humanoid_virtual_twin)/meshes/Right_Forearm.stl" scale="0.001 0.001 0.001"/>
            </geometry>
        </collision> -->
        <inertial>
            <origin xyz="0 0 -93.816e-3" rpy="0 0 0"/>
            <mass value="0.094"/>
            <inertia ixx="228.969e-6" iyy="231.48e-6" izz="16.247e-6" ixy="0" ixz="0"  iyz="0.002e-6"/>
        </inertial>
    </link>
    <gazebo reference="LFAy">
        <implicitSpringDamper>${Damper_val}</implicitSpringDamper>
        <springStiffness>${springstiffness_val}</springStiffness>
        <springReference>${springReference_val}</springReference>
        <stopErp>${stopErp_val}</stopErp>
        <stopCfm>${stopCfm_val}</stopCfm>
    </gazebo>
    <gazebo reference="Left_Forearm">
        <material>Gazebo/Grey</material>
        <!-- <mu1 value="${mu1_val}"/>
        <mu2 value="${mu2_val}"/>
        <kp value="${kp_val}" />
        <kd value="${kd_val}" />
        <maxVel value="${maxVel_val}"/>
        <dampingFactor value="${dampigFactor_val}"/>
        <selfCollide>${selfCollide_val}</selfCollide>   -->
    </gazebo>
</robot>
  