<?xml version="1.0"?>
<robot xmlns:xacro="http://www.ros.org/wiki/xacro" >
    <joint name="LFy" type="revolute">
      <origin xyz="0 0 -128e-3" rpy="0 0 0"/>
      <parent link="Left_Shank"/>
      <child link="Left_Ankle"/>
      <axis xyz="0 -1.0 0"/>
      <limit lower="${-pi/2}" upper="${pi/2}" effort="${maxeffort_val}" velocity="${maxVel_val}"/>
      <xacro:if value="$(arg use_URDF_joint_dynamics_coefficients)">
          <dynamics damping="${damping_val}" friction="${friction_val}"/>
      </xacro:if>
    </joint>
	<link name="Left_Ankle">
      <visual>
        <origin xyz="0 0 0" rpy="0 0 0"/>
        <geometry>
          <mesh filename="file://$(find ros2_humanoid_virtual_twin)/meshes/Left-Ankle.stl"/>
        </geometry>
        <material name="grey"/>
      </visual>
      <collision>
        <origin xyz="0 0 0" rpy="0 0 0"/>
        <geometry>
            <mesh filename="file://$(find ros2_humanoid_virtual_twin)/meshes/Left-Ankle-Collision.stl"/>
        </geometry>
      </collision>
      <inertial>
        <origin xyz="-20.881e-3	0.167e-3	14.849e-3" rpy="0 0 0"/>
        <mass value="0.294"/>
        <inertia ixx="115.377e-6" iyy="266.21e-6" izz="222.99e-6" ixy="-1.023e-6" ixz="4.663e-6"  iyz="1.655e-6" />
      </inertial>      
    </link> 
    <xacro:if value="$(arg use_gazebo_joint_physics_coefficients)">
    <gazebo reference="LFy">
        <implicitSpringDamper>${Damper_val}</implicitSpringDamper>
        <springStiffness>${springstiffness_val}</springStiffness>
        <springReference>${springReference_val}</springReference>
        <stopErp>${stopErp_val}</stopErp>
        <stopCfm>${stopCfm_val}</stopCfm>
    </gazebo>    
    </xacro:if>
    <gazebo reference="Left_Ankle">
        <material>Gazebo/Grey</material>
        <xacro:if value="$(arg use_gazebo_link_physics_coefficients)">
          <mu1 value="${mu1_val}"/>
          <mu2 value="${mu2_val}"/>
          <kp value="${kp_val}" />
          <kd value="${kd_val}" />
          <maxVel value="${maxVel_val}"/>
          <dampingFactor value="${dampigFactor_val}"/>
          <selfCollide>${selfCollide_val}</selfCollide>  
        </xacro:if>
    </gazebo> 
</robot>
