<?xml version="1.0"?>
<robot xmlns:xacro="http://www.ros.org/wiki/xacro">
    <joint name="Hz" type="revolute">
        <origin xyz="18.061e-3 0.134e-3 42.5e-3" rpy="0 0 0"/>
        <parent link="Trunk"/>
        <child link="Head_Mounting"/>
        <axis xyz="0 0 1.0"/>
        <limit lower="${-pi/2}" upper="${pi/2}" effort="100" velocity="100"/>
    </joint>
    <link name="Head_Mounting">
        <visual>
            <origin xyz="0 0 0" rpy="0 0 0"/>
            <geometry>
                <mesh filename="file://$(find ros2_humanoid_virtual_twin)/meshes/HeadMounting.stl"/>
            </geometry>
            <material name="grey"/>
        </visual>
        <collision>
            <origin xyz="0 0 0" rpy="0 0 0"/>
            <geometry>
                <mesh filename="file://$(find ros2_humanoid_virtual_twin)/meshes/Head-Mounting-Collision.stl"/>
            </geometry>
        </collision>
        <inertial>
            <origin xyz="0 -3.335e-3 -17.703e-3" rpy="0 0 0"/>
            <mass value="0.011"/>
            <inertia ixx="4.859e-6" iyy="2.246e-6" izz="3.894e-6" ixy="0" ixz="0"  iyz="0.637e-6"/>
        </inertial>
    </link>
    <gazebo reference="Head_Mounting">
        <material>Gazebo/Grey</material>
        <mu1 value="200.0"/>
        <mu2 value="100.0"/>
        <kp value="10000000.0" />
        <kd value="1.0" />
        <selfCollide>true</selfCollide>
    </gazebo>
</robot>